Traceback (most recent call last):
  File "/Users/simplypatrickg/anaconda3/lib/python3.8/site-packages/jupyter_cache/executors/utils.py", line 51, in single_nb_execution
    executenb(
  File "/Users/simplypatrickg/anaconda3/lib/python3.8/site-packages/nbclient/client.py", line 1112, in execute
    return NotebookClient(nb=nb, resources=resources, km=km, **kwargs).execute()
  File "/Users/simplypatrickg/anaconda3/lib/python3.8/site-packages/nbclient/util.py", line 74, in wrapped
    return just_run(coro(*args, **kwargs))
  File "/Users/simplypatrickg/anaconda3/lib/python3.8/site-packages/nbclient/util.py", line 53, in just_run
    return loop.run_until_complete(coro)
  File "/Users/simplypatrickg/anaconda3/lib/python3.8/asyncio/base_events.py", line 616, in run_until_complete
    return future.result()
  File "/Users/simplypatrickg/anaconda3/lib/python3.8/site-packages/nbclient/client.py", line 553, in async_execute
    await self.async_execute_cell(
  File "/Users/simplypatrickg/anaconda3/lib/python3.8/site-packages/nbclient/client.py", line 857, in async_execute_cell
    self._check_raise_for_error(cell, exec_reply)
  File "/Users/simplypatrickg/anaconda3/lib/python3.8/site-packages/nbclient/client.py", line 760, in _check_raise_for_error
    raise CellExecutionError.from_cell_and_msg(cell, exec_reply_content)
nbclient.exceptions.CellExecutionError: An error occurred while executing the following cell:
------------------
num_epochs = 30
early_stop = EarlyStopping(monitor='val_loss', patience=2)
history = LSTM_model.fit(training_padded, train_labels, epochs=num_epochs, validation_data=(testing_padded, test_labels),callbacks =[early_stop], verbose=2)
------------------

[0;31m---------------------------------------------------------------------------[0m
[0;31mValueError[0m                                Traceback (most recent call last)
[0;32m/var/folders/6d/prnzxhkn7tj95jgrjcvd1j5r0000gn/T/ipykernel_73687/2211669581.py[0m in [0;36m<module>[0;34m[0m
[1;32m      1[0m [0mnum_epochs[0m [0;34m=[0m [0;36m30[0m[0;34m[0m[0;34m[0m[0m
[1;32m      2[0m [0mearly_stop[0m [0;34m=[0m [0mEarlyStopping[0m[0;34m([0m[0mmonitor[0m[0;34m=[0m[0;34m'val_loss'[0m[0;34m,[0m [0mpatience[0m[0;34m=[0m[0;36m2[0m[0;34m)[0m[0;34m[0m[0;34m[0m[0m
[0;32m----> 3[0;31m [0mhistory[0m [0;34m=[0m [0mLSTM_model[0m[0;34m.[0m[0mfit[0m[0;34m([0m[0mtraining_padded[0m[0;34m,[0m [0mtrain_labels[0m[0;34m,[0m [0mepochs[0m[0;34m=[0m[0mnum_epochs[0m[0;34m,[0m [0mvalidation_data[0m[0;34m=[0m[0;34m([0m[0mtesting_padded[0m[0;34m,[0m [0mtest_labels[0m[0;34m)[0m[0;34m,[0m[0mcallbacks[0m [0;34m=[0m[0;34m[[0m[0mearly_stop[0m[0;34m][0m[0;34m,[0m [0mverbose[0m[0;34m=[0m[0;36m2[0m[0;34m)[0m[0;34m[0m[0;34m[0m[0m
[0m
[0;32m~/.local/lib/python3.8/site-packages/keras/utils/traceback_utils.py[0m in [0;36merror_handler[0;34m(*args, **kwargs)[0m
[1;32m     65[0m     [0;32mexcept[0m [0mException[0m [0;32mas[0m [0me[0m[0;34m:[0m  [0;31m# pylint: disable=broad-except[0m[0;34m[0m[0;34m[0m[0m
[1;32m     66[0m       [0mfiltered_tb[0m [0;34m=[0m [0m_process_traceback_frames[0m[0;34m([0m[0me[0m[0;34m.[0m[0m__traceback__[0m[0;34m)[0m[0;34m[0m[0;34m[0m[0m
[0;32m---> 67[0;31m       [0;32mraise[0m [0me[0m[0;34m.[0m[0mwith_traceback[0m[0;34m([0m[0mfiltered_tb[0m[0;34m)[0m [0;32mfrom[0m [0;32mNone[0m[0;34m[0m[0;34m[0m[0m
[0m[1;32m     68[0m     [0;32mfinally[0m[0;34m:[0m[0;34m[0m[0;34m[0m[0m
[1;32m     69[0m       [0;32mdel[0m [0mfiltered_tb[0m[0;34m[0m[0;34m[0m[0m

[0;32m~/.local/lib/python3.8/site-packages/tensorflow/python/framework/func_graph.py[0m in [0;36mautograph_handler[0;34m(*args, **kwargs)[0m
[1;32m   1127[0m           [0;32mexcept[0m [0mException[0m [0;32mas[0m [0me[0m[0;34m:[0m  [0;31m# pylint:disable=broad-except[0m[0;34m[0m[0;34m[0m[0m
[1;32m   1128[0m             [0;32mif[0m [0mhasattr[0m[0;34m([0m[0me[0m[0;34m,[0m [0;34m"ag_error_metadata"[0m[0;34m)[0m[0;34m:[0m[0;34m[0m[0;34m[0m[0m
[0;32m-> 1129[0;31m               [0;32mraise[0m [0me[0m[0;34m.[0m[0mag_error_metadata[0m[0;34m.[0m[0mto_exception[0m[0;34m([0m[0me[0m[0;34m)[0m[0;34m[0m[0;34m[0m[0m
[0m[1;32m   1130[0m             [0;32melse[0m[0;34m:[0m[0;34m[0m[0;34m[0m[0m
[1;32m   1131[0m               [0;32mraise[0m[0;34m[0m[0;34m[0m[0m

[0;31mValueError[0m: in user code:

    File "/Users/simplypatrickg/.local/lib/python3.8/site-packages/keras/engine/training.py", line 878, in train_function  *
        return step_function(self, iterator)
    File "/Users/simplypatrickg/.local/lib/python3.8/site-packages/keras/engine/training.py", line 867, in step_function  **
        outputs = model.distribute_strategy.run(run_step, args=(data,))
    File "/Users/simplypatrickg/.local/lib/python3.8/site-packages/keras/engine/training.py", line 860, in run_step  **
        outputs = model.train_step(data)
    File "/Users/simplypatrickg/.local/lib/python3.8/site-packages/keras/engine/training.py", line 809, in train_step
        loss = self.compiled_loss(
    File "/Users/simplypatrickg/.local/lib/python3.8/site-packages/keras/engine/compile_utils.py", line 201, in __call__
        loss_value = loss_obj(y_t, y_p, sample_weight=sw)
    File "/Users/simplypatrickg/.local/lib/python3.8/site-packages/keras/losses.py", line 141, in __call__
        losses = call_fn(y_true, y_pred)
    File "/Users/simplypatrickg/.local/lib/python3.8/site-packages/keras/losses.py", line 245, in call  **
        return ag_fn(y_true, y_pred, **self._fn_kwargs)
    File "/Users/simplypatrickg/.local/lib/python3.8/site-packages/keras/losses.py", line 1807, in binary_crossentropy
        backend.binary_crossentropy(y_true, y_pred, from_logits=from_logits),
    File "/Users/simplypatrickg/.local/lib/python3.8/site-packages/keras/backend.py", line 5158, in binary_crossentropy
        return tf.nn.sigmoid_cross_entropy_with_logits(labels=target, logits=output)

    ValueError: `logits` and `labels` must have the same shape, received ((32, 50, 1) vs (32,)).

ValueError: in user code:

    File "/Users/simplypatrickg/.local/lib/python3.8/site-packages/keras/engine/training.py", line 878, in train_function  *
        return step_function(self, iterator)
    File "/Users/simplypatrickg/.local/lib/python3.8/site-packages/keras/engine/training.py", line 867, in step_function  **
        outputs = model.distribute_strategy.run(run_step, args=(data,))
    File "/Users/simplypatrickg/.local/lib/python3.8/site-packages/keras/engine/training.py", line 860, in run_step  **
        outputs = model.train_step(data)
    File "/Users/simplypatrickg/.local/lib/python3.8/site-packages/keras/engine/training.py", line 809, in train_step
        loss = self.compiled_loss(
    File "/Users/simplypatrickg/.local/lib/python3.8/site-packages/keras/engine/compile_utils.py", line 201, in __call__
        loss_value = loss_obj(y_t, y_p, sample_weight=sw)
    File "/Users/simplypatrickg/.local/lib/python3.8/site-packages/keras/losses.py", line 141, in __call__
        losses = call_fn(y_true, y_pred)
    File "/Users/simplypatrickg/.local/lib/python3.8/site-packages/keras/losses.py", line 245, in call  **
        return ag_fn(y_true, y_pred, **self._fn_kwargs)
    File "/Users/simplypatrickg/.local/lib/python3.8/site-packages/keras/losses.py", line 1807, in binary_crossentropy
        backend.binary_crossentropy(y_true, y_pred, from_logits=from_logits),
    File "/Users/simplypatrickg/.local/lib/python3.8/site-packages/keras/backend.py", line 5158, in binary_crossentropy
        return tf.nn.sigmoid_cross_entropy_with_logits(labels=target, logits=output)

    ValueError: `logits` and `labels` must have the same shape, received ((32, 50, 1) vs (32,)).


