Traceback (most recent call last):
  File "/Users/simplypatrickg/anaconda3/lib/python3.8/site-packages/jupyter_cache/executors/utils.py", line 51, in single_nb_execution
    executenb(
  File "/Users/simplypatrickg/anaconda3/lib/python3.8/site-packages/nbclient/client.py", line 1112, in execute
    return NotebookClient(nb=nb, resources=resources, km=km, **kwargs).execute()
  File "/Users/simplypatrickg/anaconda3/lib/python3.8/site-packages/nbclient/util.py", line 74, in wrapped
    return just_run(coro(*args, **kwargs))
  File "/Users/simplypatrickg/anaconda3/lib/python3.8/site-packages/nbclient/util.py", line 53, in just_run
    return loop.run_until_complete(coro)
  File "/Users/simplypatrickg/anaconda3/lib/python3.8/asyncio/base_events.py", line 616, in run_until_complete
    return future.result()
  File "/Users/simplypatrickg/anaconda3/lib/python3.8/site-packages/nbclient/client.py", line 553, in async_execute
    await self.async_execute_cell(
  File "/Users/simplypatrickg/anaconda3/lib/python3.8/site-packages/nbclient/client.py", line 857, in async_execute_cell
    self._check_raise_for_error(cell, exec_reply)
  File "/Users/simplypatrickg/anaconda3/lib/python3.8/site-packages/nbclient/client.py", line 760, in _check_raise_for_error
    raise CellExecutionError.from_cell_and_msg(cell, exec_reply_content)
nbclient.exceptions.CellExecutionError: An error occurred while executing the following cell:
------------------
# Demonstrate why the date_activ column cannot replace completely date_first_activ
activity = ['date_activ','date_first_activ']

# Filter the columns of interest
pco_activity = pco_main[activity]

# Obtain only the complete cases
pco_activity_cc = pco_activity.dropna(subset=['date_first_activ'],how='any',inplace=False)

# Test whether two objects contain the same elements.
pco_activity_cc.date_activ.equals(pco_activity_cc.date_first_activ)

# Describe it
pco_activity_cc.describe(datetime_is_numeric=True)
------------------

[0;31m---------------------------------------------------------------------------[0m
[0;31mTypeError[0m                                 Traceback (most recent call last)
[0;32m/var/folders/6d/prnzxhkn7tj95jgrjcvd1j5r0000gn/T/ipykernel_66077/1267575529.py[0m in [0;36m<module>[0;34m[0m
[1;32m     12[0m [0;34m[0m[0m
[1;32m     13[0m [0;31m# Describe it[0m[0;34m[0m[0;34m[0m[0;34m[0m[0m
[0;32m---> 14[0;31m [0mpco_activity_cc[0m[0;34m.[0m[0mdescribe[0m[0;34m([0m[0mdatetime_is_numeric[0m[0;34m=[0m[0;32mTrue[0m[0;34m)[0m[0;34m[0m[0;34m[0m[0m
[0m
[0;31mTypeError[0m: describe() got an unexpected keyword argument 'datetime_is_numeric'
TypeError: describe() got an unexpected keyword argument 'datetime_is_numeric'

