Traceback (most recent call last):
  File "/opt/hostedtoolcache/Python/3.8.13/x64/lib/python3.8/site-packages/jupyter_cache/executors/utils.py", line 51, in single_nb_execution
    executenb(
  File "/opt/hostedtoolcache/Python/3.8.13/x64/lib/python3.8/site-packages/nbclient/client.py", line 1204, in execute
    return NotebookClient(nb=nb, resources=resources, km=km, **kwargs).execute()
  File "/opt/hostedtoolcache/Python/3.8.13/x64/lib/python3.8/site-packages/nbclient/util.py", line 84, in wrapped
    return just_run(coro(*args, **kwargs))
  File "/opt/hostedtoolcache/Python/3.8.13/x64/lib/python3.8/site-packages/nbclient/util.py", line 62, in just_run
    return loop.run_until_complete(coro)
  File "/opt/hostedtoolcache/Python/3.8.13/x64/lib/python3.8/asyncio/base_events.py", line 616, in run_until_complete
    return future.result()
  File "/opt/hostedtoolcache/Python/3.8.13/x64/lib/python3.8/site-packages/nbclient/client.py", line 663, in async_execute
    await self.async_execute_cell(
  File "/opt/hostedtoolcache/Python/3.8.13/x64/lib/python3.8/site-packages/nbclient/client.py", line 965, in async_execute_cell
    await self._check_raise_for_error(cell, cell_index, exec_reply)
  File "/opt/hostedtoolcache/Python/3.8.13/x64/lib/python3.8/site-packages/nbclient/client.py", line 862, in _check_raise_for_error
    raise CellExecutionError.from_cell_and_msg(cell, exec_reply_content)
nbclient.exceptions.CellExecutionError: An error occurred while executing the following cell:
------------------
betas = best_model[1].feature_importances_
plt.figure(figsize=(12,6))
plt.barh(features, betas)
plt.show()
------------------

[0;31m---------------------------------------------------------------------------[0m
[0;31mIndexError[0m                                Traceback (most recent call last)
Input [0;32mIn [22][0m, in [0;36m<cell line: 1>[0;34m()[0m
[0;32m----> 1[0m betas [38;5;241m=[39m [43mbest_model[49m[43m[[49m[38;5;241;43m1[39;49m[43m][49m[38;5;241m.[39mfeature_importances_
[1;32m      2[0m plt[38;5;241m.[39mfigure(figsize[38;5;241m=[39m([38;5;241m12[39m,[38;5;241m6[39m))
[1;32m      3[0m plt[38;5;241m.[39mbarh(features, betas)

File [0;32m/opt/hostedtoolcache/Python/3.8.13/x64/lib/python3.8/site-packages/sklearn/pipeline.py:265[0m, in [0;36mPipeline.__getitem__[0;34m(self, ind)[0m
[1;32m    261[0m     [38;5;28;01mreturn[39;00m [38;5;28mself[39m[38;5;241m.[39m[38;5;18m__class__[39m(
[1;32m    262[0m         [38;5;28mself[39m[38;5;241m.[39msteps[ind], memory[38;5;241m=[39m[38;5;28mself[39m[38;5;241m.[39mmemory, verbose[38;5;241m=[39m[38;5;28mself[39m[38;5;241m.[39mverbose
[1;32m    263[0m     )
[1;32m    264[0m [38;5;28;01mtry[39;00m:
[0;32m--> 265[0m     name, est [38;5;241m=[39m [38;5;28;43mself[39;49m[38;5;241;43m.[39;49m[43msteps[49m[43m[[49m[43mind[49m[43m][49m
[1;32m    266[0m [38;5;28;01mexcept[39;00m [38;5;167;01mTypeError[39;00m:
[1;32m    267[0m     [38;5;66;03m# Not an int, try get step by name[39;00m
[1;32m    268[0m     [38;5;28;01mreturn[39;00m [38;5;28mself[39m[38;5;241m.[39mnamed_steps[ind]

[0;31mIndexError[0m: list index out of range
IndexError: list index out of range

