Traceback (most recent call last):
  File "/opt/hostedtoolcache/Python/3.8.13/x64/lib/python3.8/site-packages/jupyter_cache/executors/utils.py", line 51, in single_nb_execution
    executenb(
  File "/opt/hostedtoolcache/Python/3.8.13/x64/lib/python3.8/site-packages/nbclient/client.py", line 1204, in execute
    return NotebookClient(nb=nb, resources=resources, km=km, **kwargs).execute()
  File "/opt/hostedtoolcache/Python/3.8.13/x64/lib/python3.8/site-packages/nbclient/util.py", line 84, in wrapped
    return just_run(coro(*args, **kwargs))
  File "/opt/hostedtoolcache/Python/3.8.13/x64/lib/python3.8/site-packages/nbclient/util.py", line 62, in just_run
    return loop.run_until_complete(coro)
  File "/opt/hostedtoolcache/Python/3.8.13/x64/lib/python3.8/asyncio/base_events.py", line 616, in run_until_complete
    return future.result()
  File "/opt/hostedtoolcache/Python/3.8.13/x64/lib/python3.8/site-packages/nbclient/client.py", line 663, in async_execute
    await self.async_execute_cell(
  File "/opt/hostedtoolcache/Python/3.8.13/x64/lib/python3.8/site-packages/nbclient/client.py", line 965, in async_execute_cell
    await self._check_raise_for_error(cell, cell_index, exec_reply)
  File "/opt/hostedtoolcache/Python/3.8.13/x64/lib/python3.8/site-packages/nbclient/client.py", line 862, in _check_raise_for_error
    raise CellExecutionError.from_cell_and_msg(cell, exec_reply_content)
nbclient.exceptions.CellExecutionError: An error occurred while executing the following cell:
------------------
STOCK = TICKER_LIST[0]
DATE = list(scored_news.date)[-1]

# Set the index to ticker and date
single_day = scored_news_clean.set_index(['ticker', 'date'])
# Cross-section the STOCK row
single_day = single_day.loc[STOCK]
# Select the DATE
single_day = single_day.loc[DATE]
# Set the index to time and 
single_day = single_day.set_index('time')
# Sort it
single_day = single_day.sort_index()
------------------

[0;31m---------------------------------------------------------------------------[0m
[0;31mKeyError[0m                                  Traceback (most recent call last)
File [0;32m/opt/hostedtoolcache/Python/3.8.13/x64/lib/python3.8/site-packages/pandas/core/indexes/base.py:3621[0m, in [0;36mIndex.get_loc[0;34m(self, key, method, tolerance)[0m
[1;32m   3620[0m [38;5;28;01mtry[39;00m:
[0;32m-> 3621[0m     [38;5;28;01mreturn[39;00m [38;5;28;43mself[39;49m[38;5;241;43m.[39;49m[43m_engine[49m[38;5;241;43m.[39;49m[43mget_loc[49m[43m([49m[43mcasted_key[49m[43m)[49m
[1;32m   3622[0m [38;5;28;01mexcept[39;00m [38;5;167;01mKeyError[39;00m [38;5;28;01mas[39;00m err:

File [0;32m/opt/hostedtoolcache/Python/3.8.13/x64/lib/python3.8/site-packages/pandas/_libs/index.pyx:136[0m, in [0;36mpandas._libs.index.IndexEngine.get_loc[0;34m()[0m

File [0;32m/opt/hostedtoolcache/Python/3.8.13/x64/lib/python3.8/site-packages/pandas/_libs/index.pyx:160[0m, in [0;36mpandas._libs.index.IndexEngine.get_loc[0;34m()[0m

File [0;32m/opt/hostedtoolcache/Python/3.8.13/x64/lib/python3.8/site-packages/pandas/_libs/index.pyx:201[0m, in [0;36mpandas._libs.index.IndexEngine._get_loc_duplicates[0;34m()[0m

File [0;32m/opt/hostedtoolcache/Python/3.8.13/x64/lib/python3.8/site-packages/pandas/_libs/index.pyx:209[0m, in [0;36mpandas._libs.index.IndexEngine._maybe_get_bool_indexer[0;34m()[0m

File [0;32m/opt/hostedtoolcache/Python/3.8.13/x64/lib/python3.8/site-packages/pandas/_libs/index.pyx:107[0m, in [0;36mpandas._libs.index._unpack_bool_indexer[0;34m()[0m

[0;31mKeyError[0m: datetime.date(2022, 8, 13)

The above exception was the direct cause of the following exception:

[0;31mKeyError[0m                                  Traceback (most recent call last)
Input [0;32mIn [11][0m, in [0;36m<cell line: 9>[0;34m()[0m
[1;32m      7[0m single_day [38;5;241m=[39m single_day[38;5;241m.[39mloc[STOCK]
[1;32m      8[0m [38;5;66;03m# Select the DATE[39;00m
[0;32m----> 9[0m single_day [38;5;241m=[39m [43msingle_day[49m[38;5;241;43m.[39;49m[43mloc[49m[43m[[49m[43mDATE[49m[43m][49m
[1;32m     10[0m [38;5;66;03m# Set the index to time and [39;00m
[1;32m     11[0m single_day [38;5;241m=[39m single_day[38;5;241m.[39mset_index([38;5;124m'[39m[38;5;124mtime[39m[38;5;124m'[39m)

File [0;32m/opt/hostedtoolcache/Python/3.8.13/x64/lib/python3.8/site-packages/pandas/core/indexing.py:967[0m, in [0;36m_LocationIndexer.__getitem__[0;34m(self, key)[0m
[1;32m    964[0m axis [38;5;241m=[39m [38;5;28mself[39m[38;5;241m.[39maxis [38;5;129;01mor[39;00m [38;5;241m0[39m
[1;32m    966[0m maybe_callable [38;5;241m=[39m com[38;5;241m.[39mapply_if_callable(key, [38;5;28mself[39m[38;5;241m.[39mobj)
[0;32m--> 967[0m [38;5;28;01mreturn[39;00m [38;5;28;43mself[39;49m[38;5;241;43m.[39;49m[43m_getitem_axis[49m[43m([49m[43mmaybe_callable[49m[43m,[49m[43m [49m[43maxis[49m[38;5;241;43m=[39;49m[43maxis[49m[43m)[49m

File [0;32m/opt/hostedtoolcache/Python/3.8.13/x64/lib/python3.8/site-packages/pandas/core/indexing.py:1202[0m, in [0;36m_LocIndexer._getitem_axis[0;34m(self, key, axis)[0m
[1;32m   1200[0m [38;5;66;03m# fall thru to straight lookup[39;00m
[1;32m   1201[0m [38;5;28mself[39m[38;5;241m.[39m_validate_key(key, axis)
[0;32m-> 1202[0m [38;5;28;01mreturn[39;00m [38;5;28;43mself[39;49m[38;5;241;43m.[39;49m[43m_get_label[49m[43m([49m[43mkey[49m[43m,[49m[43m [49m[43maxis[49m[38;5;241;43m=[39;49m[43maxis[49m[43m)[49m

File [0;32m/opt/hostedtoolcache/Python/3.8.13/x64/lib/python3.8/site-packages/pandas/core/indexing.py:1153[0m, in [0;36m_LocIndexer._get_label[0;34m(self, label, axis)[0m
[1;32m   1151[0m [38;5;28;01mdef[39;00m [38;5;21m_get_label[39m([38;5;28mself[39m, label, axis: [38;5;28mint[39m):
[1;32m   1152[0m     [38;5;66;03m# GH#5667 this will fail if the label is not present in the axis.[39;00m
[0;32m-> 1153[0m     [38;5;28;01mreturn[39;00m [38;5;28;43mself[39;49m[38;5;241;43m.[39;49m[43mobj[49m[38;5;241;43m.[39;49m[43mxs[49m[43m([49m[43mlabel[49m[43m,[49m[43m [49m[43maxis[49m[38;5;241;43m=[39;49m[43maxis[49m[43m)[49m

File [0;32m/opt/hostedtoolcache/Python/3.8.13/x64/lib/python3.8/site-packages/pandas/core/generic.py:3864[0m, in [0;36mNDFrame.xs[0;34m(self, key, axis, level, drop_level)[0m
[1;32m   3862[0m             new_index [38;5;241m=[39m index[loc]
[1;32m   3863[0m [38;5;28;01melse[39;00m:
[0;32m-> 3864[0m     loc [38;5;241m=[39m [43mindex[49m[38;5;241;43m.[39;49m[43mget_loc[49m[43m([49m[43mkey[49m[43m)[49m
[1;32m   3866[0m     [38;5;28;01mif[39;00m [38;5;28misinstance[39m(loc, np[38;5;241m.[39mndarray):
[1;32m   3867[0m         [38;5;28;01mif[39;00m loc[38;5;241m.[39mdtype [38;5;241m==[39m np[38;5;241m.[39mbool_:

File [0;32m/opt/hostedtoolcache/Python/3.8.13/x64/lib/python3.8/site-packages/pandas/core/indexes/base.py:3623[0m, in [0;36mIndex.get_loc[0;34m(self, key, method, tolerance)[0m
[1;32m   3621[0m     [38;5;28;01mreturn[39;00m [38;5;28mself[39m[38;5;241m.[39m_engine[38;5;241m.[39mget_loc(casted_key)
[1;32m   3622[0m [38;5;28;01mexcept[39;00m [38;5;167;01mKeyError[39;00m [38;5;28;01mas[39;00m err:
[0;32m-> 3623[0m     [38;5;28;01mraise[39;00m [38;5;167;01mKeyError[39;00m(key) [38;5;28;01mfrom[39;00m [38;5;21;01merr[39;00m
[1;32m   3624[0m [38;5;28;01mexcept[39;00m [38;5;167;01mTypeError[39;00m:
[1;32m   3625[0m     [38;5;66;03m# If we have a listlike key, _check_indexing_error will raise[39;00m
[1;32m   3626[0m     [38;5;66;03m#  InvalidIndexError. Otherwise we fall through and re-raise[39;00m
[1;32m   3627[0m     [38;5;66;03m#  the TypeError.[39;00m
[1;32m   3628[0m     [38;5;28mself[39m[38;5;241m.[39m_check_indexing_error(key)

[0;31mKeyError[0m: datetime.date(2022, 8, 13)
KeyError: datetime.date(2022, 8, 13)

